Workbook

Sheet Cover & Assumptions
A1: Whitmore Structured Credit Opportunities Fund II, L.P.
A2: Structured Debt & Derivatives Sleeve — KPI Workings | Prepared for Analytics & Investment Ops Working Group | Period: FY2025 / as of 31-Dec-2025
B4: Purpose | C4: This workbook supports the four KPI questions in the GP memo (01_Fund_Overview_Memo): (1) net yield to the sleeve, before/after leverage cost; (2) whether the hedges are actually hedging; (3) counterparty concentration; (4) recognition vs. cash timing gaps.
B5: How to use | C5: Each tab reproduces the source data (blue = input, taken from the case files) and builds the KPI in black formulas. Where the source documents were silent, ambiguous, or contradictory, the assumption made is logged below AND repeated as a cell comment on the tab where it's used.
B7: ASSUMPTIONS LOG — EVERY JUDGMENT CALL USED IN THIS WORKBOOK
B8: # | C8: Open Item | D8: Assumption Made / Treatment Chosen | E8: Basis / Source | F8: Tab(s) Affected
B9: A1 | C9: IRS cash ledger shows two same-day “SWAP_NET” entries (+$1,250,000 and −$1,725,000), flagged by ops as likely one erroneous duplicate. | D9: Treat −$1,725,000 (fund net-pays) as the true Q3 settlement, since the swap's YE fair value to the fund is negative (fund is out-of-the-money, paying more fixed than it receives floating). The +$1,250,000 entry is excluded from cash-flow KPIs as a duplicate/reversal, but left visible in the recon tab. | E9: 07_IRS confirm YE mark -$3.84M to Fund; 12_Cash_Ledger flags “CHECK” itself. | F9: IRS, Cash_Recon, KPI_Summary
B10: A2 | C10: CDS-0011 (Orion) settlement direction contested between the confirm's plain reading, a reciprocal confirm on file, and the broker statement. | D10: Fund is Protection Buyer (Fixed Rate Payer). USD 14,437,500 auction settlement is a RECEIPT to the fund. | E10: PM notes (11) give explicit trade rationale + evidence (fund has been paying, not receiving, the 100bp premium quarterly — see SWAP_PREM_OUT in cash ledger); cash ledger already booked it as a receipt. | F10: CDS, Cash_Recon, Concentration_Test, KPI_Summary
B11: A3 | C11: GBP forward (WTM-FX-0044) confirm has the Fund BUYING GBP, which PM notes flag as the wrong direction to hedge a GBP loan RECEIPT (should be selling GBP forward). | D11: Model the hedge as-executed (Fund long GBP forward), per PM's explicit instruction to assume “the confirm is what got done.” Hedge effectiveness is therefore computed as NEGATIVE / non-offsetting, not corrected to what should have happened. | E11: PM Trading Notes (11), FX section, final instruction. | F11: FX_Forwards, KPI_Summary
B12: A4 | C12: Content library lease (Longwood, $450k/qtr): Fund Accounting nets it against sub-licence royalty revenue in the Entertainment sleeve; Portfolio treats it as an investment cost of THIS (credit/derivatives) sleeve. | D12: For this sleeve's KPI purposes, adopt the PM/Portfolio view: treat the lease payment as an investment cost of the capital-light structure and pull the associated sub-licence royalty income into this sleeve's yield calc alongside it (both legs shown together, netted). | E12: 01_Fund_Overview §3(f); 11_PM_Trading_Notes “Leased Content Library”; 14_Lease_Registry note 2. | F12: Leases, KPI_Summary
B13: A5 | C13: Orion mezzanine (WTM-L-0002, $25.0mm face) carrying value for concentration/exposure purposes post-restructuring. | D13: Mark at CDS auction-implied recovery (42.25% of face = $10,562,500) from the 30-Sep-2025 RSA effective date, consistent with Corporate Actions Notice 1's instruction to reconcile any writedown with the CDS auction result. | E13: 16_Corporate_Actions Notice 1, item 6; Notice 5 concentration scenarios. | F13: Loan_Book, Concentration_Test
B14: A6 | C14: JPY forward (WTM-FX-0045) sized to the ORIGINAL loan notional (JPY 2,400,000,000); loan notional reset in Nov-2025 to JPY 2,737,800,000 per the loan's annual USD-linked reset mechanism. | D14: Treat the hedge as under-sized by JPY 337,800,000 (~USD 2.15mm at YE spot) rather than re-sizing it retroactively — this is a live hedge-effectiveness finding, not an error to fix in the model. | E14: 16_Corporate_Actions Notice 4. | F14: FX_Forwards, KPI_Summary
B15: A7 | C15: Loan book de-duplication across Alpha/Beta tapes and within Alpha's own tape. | D15: Count each loan once: Orion mezz counted via WTM-L-0002 only (WTM-L-0010 dropped, tape says “duplicate—do not double-count”). Timberline counted via Alpha WTM-L-0011 post-transfer only (Beta BLA-0044/45 pre-transfer dropped), balance corrected to $30,500,000 per prepayment notice (Alpha's $35,000,000 is stale). Haruki counted via Alpha WTM-L-0009 (USD) only (Beta BLA-0102 JPY line is the same asset in local currency, per Corp Actions Notice 4, not an additional exposure). Solara counted via Alpha WTM-L-0006 ($32mm drawn, matches revolver utilization report) only (Beta BLA-0156 dropped, same facility “reported differently”). | E15: 01_Memo §3(a); 04_Beta tape notes (i)-(iii); 16_Corp Actions Notices 3 & 4; 05_Revolver report. | F15: Loan_Book
B16: A8 | C16: Dawnridge Post-Prod (transferred Beta→Alpha 01-Dec-25) does not appear on the Alpha Q4 tape provided. | D16: Retain the Beta-reported balance ($14,000,000) as the best available figure and flag it as pending confirmation on Alpha's Q1-26 tape, rather than dropping the loan. | E16: 04_Beta tape, BLA-0141 note. | F16: Loan_Book
B17: A9 | C17: FRGF OTC put fair value shown as GBp 52,000 in the Position_MV column without FX conversion (a labelled system error). | D17: Use the broker's own USD-converted figure (USD 65,442 at spot 1.2585) rather than the raw, unconverted Position_MV field. | E17: 09_Options report, “CRITICAL NOTE ON FRGF.” | F17: Options
B18: A10 | C18: SLRA OTC call (written by a founder trust on Solara, the Fund's own portfolio company) is Level-3 / model-marked at an unverified 62% vol input. | D18: Exclude SLRA's $117,500 mark-to-market from recognized sleeve P&L; show it as a memo item only, recognized on exercise or first observable price. | E18: PM Trading Notes (11), “OPTIONS” section, explicit instruction. | F18: Options, KPI_Summary
B19: A11 | C19: LMVU calls exercised 30-Dec-25 (150 contracts, 15,000 shares). | D19: Excluded from options P&L; treated as a cost-basis roll into the equity co-invest sleeve ($95.20/share effective cost), consistent with PM instruction not to double count. | E19: 09_Options activity log; 11_PM_Trading_Notes “OPTIONS.” | F19: Options, KPI_Summary
... B22: A14 | C22: IRS notional ($250mm) vs. facility exposure it's meant to hedge. | D22: Use PM's stated effective floating exposure (~$350mm, i.e. $500mm combined facilities × ~50% average revolver utilisation for the fixed Ironbridge + variable Greystone blend) as the hedge target, giving an under-hedge of ~$100mm notional. Not independently re-derived — sourced directly from PM commentary. | E22: 11_PM_Trading_Notes “IRS” section. | F22: IRS, KPI_Summary
B24: Colour key:
B25: Blue = input taken directly from a source file
B26: Black = formula computed within this workbook
B27: Green = link pulled from another tab in this workbook
B28: Yellow fill = key assumption / judgment-call cell

Sheet KPI_Summary
A1: Structured Debt & Derivatives Sleeve — Q4-2025 KPI Summary
A2: All figures link to the supporting tabs (green = cross-sheet link). See Cover & Assumptions tab for every judgment call underlying these numbers.
A4: KPI 1 — NET YIELD TO THE SLEEVE (Q4-2025, annualized where noted)
A5: Loan book — cash interest received, Q4 | B5: =Loan_Book!$J$27 -> 11395308
A6: Loan book — accrued interest income, Q4 (accrual basis) | B6: =Loan_Book!$K$27 -> 12398058
A7: Content-library sub-licence royalty income, Q4 (per Assumption A4) | B7: =Cash_Recon!$D$22+Cash_Recon!$D$23 -> 1195000
A8: Less: content-library lease cost, Q4 (Longwood + Nishimura, per A4) | B8: =-Leases!$G$12/4 -> -657205
A9: Less: CDS net premium paid/received, Q4 | B9: =SUM(CDS!$G$5:$G$7) -> -27500
A10: Gross sleeve income, Q4 (accrual basis) | B10: =B5+B6+B7+B8+B9 -> 24303661
A11: Average funded loan balance (proxy for invested capital) | B11: =Loan_Book!$G$27 -> 478017000
A12: Gross annualized yield on funded loan balance (accrual basis) | B12: =(B10*4)/B11 -> 0.20337068
A14: LESS: FUND-LEVEL LEVERAGE COST
A15: Greystone revolver interest, Q3 (actual; Q4 not isolated in data, A13) | B15: =Debt_Facilities!$D$10 -> -5250000
A16: Greystone revolver commitment fee, Q3 | B16: =Debt_Facilities!$D$11 -> -93750
A17: Ironbridge term loan interest, H2 (semi-annual, shown as-is) | B17: =Debt_Facilities!$D$20 -> -8250000
A18: IRS net swap settlement, Q3 (per Assumption A1) | B18: =IRS!$B$26 -> -1725000
A19: Total fund-level leverage cost shown (partial-period, see A13) | B19: =SUM(B15:B18) -> -15318750
A20: Net sleeve income after shown leverage cost (partial-period) | B20: =B10+B19 -> 8984911
A21: Caveat: Greystone revolver figures above are Q3 actuals (the only period the cash ledger itemises); Q4 fund-level revolver interest is a genuine data gap (Assumption A13), so “after-leverage” yield here is illustrative of the METHOD, not a clean like-for-like Q4 figure. Loan-level revolver costs (Solara, Orion RCF) are already netted into the loan book's cash/accrued interest above.
A25: KPI 2 — ARE THE HEDGES ACTUALLY HEDGING?
A26: Hedge | B26: Verdict | C26: Evidence
A27: IRS vs. Greystone revolver | B27: DIRECTIONALLY YES, size & full-period proof incomplete | C27: Correctly structured (pay-fixed vs. pay-floating facility) and the persistent SOFR-CSA basis (14.7bps/yr) is small and accepted by the desk. But notional ($250mm) is undersized vs. PM's own $350mm effective-exposure estimate, and Q4 facility interest wasn't isolated in the data to prove full-period offset (A13, A14).
A28: CDS-0011 (Orion) vs. mezz + senior loan | B28: YES | C28: $14.4375mm settlement receipt materially offset the ~$14.5mm mezz writedown to auction-implied recovery — see CDS tab reconciliation, nets to ~$0 by construction.
A29: CDS-0018 (Lumivue) vs. unitranche | B29: YES, live | C29: Long protection correctly in-the-money as spreads widened against the held loan; both sources agree on sign.
A30: CDS-0022 (Timberline Ent.) | B30: N/A — not a hedge | C30: Explicitly an unrelated-name carry/income trade, not linked to the Timberline Music Rights loan (Compliance-confirmed).
A31: GBP forward (Thornbury) | B31: NO | C31: As executed, Fund buys GBP forward while it RECEIVES GBP from the loan — same-direction exposure, not offsetting (A3). Realized a further ~$2.27mm translation loss alongside the loan's own FX exposure.
A32: JPY forward (Haruki) | B32: PARTIALLY | C32: Direction is correct (sells JPY against a JPY receivable) but under-sized by JPY 337.8mm post notional-reset (A6) — hedge ratio ~88% of current exposure.
A33: EUR forward (Equinox / unconfirmed) | B33: UNCLEAR / not a confirmed hedge | C33: No stated linkage to any loan cashflow; modelled as a stand-alone position pending strategy-tag confirmation.
A34: Content-library lease + royalty (Longwood) | B34: STRUCTURAL HEDGE, by construction, per A4 | C34: If treated as an investment cost against the royalty stream it generates (chosen treatment), net sleeve exposure is the spread between the two — economically a natural offset, not a market hedge.
A37: KPI 3 — COUNTERPARTY CONCENTRATION
A38: Orion Studios Holdings LLC exposure, mezz at recovery + CDS netted (recommended, A5) | B38: =Concentration_Test!$B$20 -> 41287500
A39: Greystone 12.5% single-name limit (USD) | B39: =Concentration_Test!$B$7 -> 48125000
A40: Headroom / (breach) | B40: =B39-B38 -> 6837500
A41: Compliance status (recommended treatment) | B41: =IF(B38<=B39,"UNDER LIMIT","OVER LIMIT — breach") -> UNDER LIMIT
A42: Result is treatment-dependent — see Concentration_Test tab for the full scenario range (agent has granted a 30-day standstill pending resolution). Consolidated by legal-entity-group per counterparty snapshot notes (Aldgate/Copperfield, Greystone/HTB, Ashford Ridge NY/London are each one relationship, not several).
A46: KPI 4 — RECOGNITION vs. CASH TIMING GAPS
A47: Item | B47: Accrued/Recognized (USD) | C47: Cash Received/Paid (USD) | D47: Gap (USD) | E47: Driver
A48: Loan book, aggregate (Loan_Book tab totals) | B48: =Loan_Book!$K$27 -> 12398058 | C48: =Loan_Book!$J$27 -> 11395308 | D48: =B48-C48 -> 1002750 | E48: Orion mezz delinquency (Q4 accrued $640,625, not received) + Haruki semi-annual pay-vs-accrual timing.
A49: CDS settlement (Orion) | B49: =CDS!$B$13 -> 14437500 | C49: =CDS!$B$13 -> 14437500 | D49: =B49-C49 -> 0 | E49: No gap — auction-driven cash settlement recognized when received; booking LAG in ledger (Sep event, Jan booking) is a processing delay, not an accrual gap.
A50: Emberlight PIK toggle (WTM-L-0013) | B50: 781250 | C50: 0 | D50: =B50-C50 -> 781250 | E50: PIK — by design, all recognized income is non-cash until toggled back to cash-pay or repaid.
...

Sheet Loan_Book
A1: Consolidated Loan Book — De-Duplicated Across Servicer Alpha & Beta Tapes
A2: Sources: 03_Loan_Book_ServicerAlpha_2025Q4.csv, 04_ServicerBeta_LoanTape_Dec25.txt, 16_Corporate_Actions_Notices.txt. See Assumptions A7-A8.
A4: Loan ID | B4: Obligor | C4: Source | D4: Ccy | E4: Local Funded Bal. | F4: FX → USD | G4: Funded Bal. (USD) | H4: Coupon | I4: Pay Freq | J4: Q4 Cash Int. Recv'd (USD) | K4: Q4 Accrued Int. Income (USD) | L4: Recog. vs Cash Gap | M4: DPD | N4: Include? | O4: Notes / Assumption
A5: WTM-L-0001 | B5: Orion Studios Holdings LLC | C5: Alpha | D5: USD | E5: 45000000 | F5: 1 | G5: =E5*F5 -> 45000000 | H5: SOFR+650 | I5: Quarterly | J5: 1148625 | K5: 1148625 | L5: =K5-J5 -> 0 | M5: 0 | N5: Y | O5: Senior term loan; paid current.
A6: WTM-L-0002 | B6: Orion Studios Holdings LLC | C6: Alpha | D6: USD | E6: 25000000 | F6: 1 | G6: =E6*F6 -> 25000000 | H6: 10.25% Fixed | I6: Quarterly | J6: 0 | K6: 640625 | L6: =K6-J6 -> 640625 | M6: 92 | N6: Y | O6: Mezz; Dec-25 coupon accrued not received (A2/A5). Recovery-adj. value for concentration = 42.25% × face, see Concentration_Test.
A7: WTM-L-0010 | B7: Orion Studios Holdings LLC | C7: Alpha | D7: USD | E7: 25000000 | F7: 1 | G7: =E7*F7 -> 25000000 | H7: 10.25% Fixed | I7: Quarterly | J7: 0 | K7: 0 | L7: =K7-J7 -> 0 | M7: 92 | N7: N | O7: EXCLUDE — tape's own note: duplicate of WTM-L-0002 (A7).
A8: WTM-L-0003 | B8: Emberlight Records Group | C8: Alpha | D8: USD | E8: 58500000 | F8: 1 | G8: =E8*F8 -> 58500000 | H8: SOFR+525 | I8: Monthly | J8: 1393875 | K8: 1393875 | L8: =K8-J8 -> 0 | M8: 0 | N8: Y | O8: Monthly pay; Q4 cash = last recorded monthly pmt × 3 (assumption, only Dec pmt shown on tape).
A9: WTM-L-0013 | B9: Emberlight Records Group (PIK toggle) | C9: Alpha | D9: USD | E9: 1850000 | F9: 1 | G9: =E9*F9 -> 1850000 | H9: 12.50% Fixed PIK | I9: PIK | J9: 0 | K9: 781250 | L9: =K9-J9 -> 781250 | M9: 0 | N9: Y | O9: 2nd consecutive PIK election; non-cash, added to principal (Corp Actions Notice 2). Clean recognition-vs-cash example.
A10: WTM-L-0004 | B10: Prismrock Live Events Inc | C10: Alpha | D10: USD | E10: 20000000 | F10: 1 | G10: =E10*F10 -> 20000000 | H10: 9.50% Fixed | I10: Quarterly | J10: 475000 | K10: 475000 | L10: =K10-J10 -> 0 | M10: 0 | N10: Y | O10: Paid current.
A11: WTM-L-0005 | B11: Lumivue Streaming Corp | C11: Alpha | D11: USD | E11: 80000000 | F11: 1 | G11: =E11*F11 -> 80000000 | H11: SOFR+700 | I11: Quarterly | J11: 2172000 | K11: 2172000 | L11: =K11-J11 -> 0 | M11: 0 | N11: Y | O11: Unitranche; paid current.
A12: WTM-L-0006 | B12: Solara Content Partners | C12: Alpha | D12: USD | E12: 32000000 | F12: 1 | G12: =E12*F12 -> 32000000 | H12: SOFR+475 | I12: Quarterly | J12: 656000 | K12: 656000 | L12: =K12-J12 -> 0 | M12: 0 | N12: Y | O12: Revolver, drawn portion; +unused fee $29,143/qtr, see Debt_Facilities. Balance ties to 05_Revolver report.
A13: WTM-L-0007 | B13: Ridgeline Post-Production LLC | C13: Alpha | D13: USD | E13: 15000000 | F13: 1 | G13: =E13*F13 -> 15000000 | H13: 11.00% Fixed | I13: Quarterly | J13: 412500 | K13: 412500 | L13: =K13-J13 -> 0 | M13: 0 | N13: Y | O13: Paid current.
A14: WTM-L-0008 | B14: Frostgate Films Ltd | C14: Alpha | D14: USD | E14: 22000000 | F14: 1 | G14: =E14*F14 -> 22000000 | H14: SOFR+600 | I14: Quarterly | J14: 529100 | K14: 529100 | L14: =K14-J14 -> 0 | M14: 0 | N14: Y | O14: GBP-denominated obligor; loan itself booked/paid in USD.
A15: WTM-L-0009 | B15: Haruki Anime Studios KK | C15: Alpha | D15: USD | E15: 18000000 | F15: 1 | G15: =E15*F15 -> 18000000 | H15: 8.75% Fixed | I15: Semi-Annual | J15: 787500 | K15: 393750 | L15: =K15-J15 -> -393750 | M15: 0 | N15: Y | O15: Semi-annual pay — Dec pmt covers Jun-Dec; only half is Q4-earned income (recognition gap). JPY notional reset Nov-25, see FX_Forwards (A6).
A16: WTM-L-0011 | B16: Timberline Music Rights I LLC | C16: Alpha | D16: USD | E16: 30500000 | F16: 1 | G16: =E16*F16 -> 30500000 | H16: 9.00% Fixed | I16: Quarterly | J16: 787500 | K16: 762125 | L16: =K16-J16 -> -25375 | M16: 0 | N16: Y | O16: Balance corrected to $30.5mm post 05-Oct-25 prepayment (tape's stale $35mm overridden, Corp Actions Notice 3). Accrual pro-rated 5 days@$35mm + 87 days@$30.5mm, Act/360. Prepay premium $45,000 (one-off, see KPI_Summary).
... A26: BLA-0102 | B26: Haruki Anime Studios KK (JPY view) | C26: Beta | D26: JPY | E26: 2400000000 | F26: 0.00752 | G26: =E26*F26 -> 18048000 | H26: 8.75% Fixed | I26: Semi-Annual | J26: 0 | K26: 0 | L26: =K26-J26 -> 0 | M26: 0 | N26: N | O26: EXCLUDE — same asset as WTM-L-0009 reported in local currency by Beta (Corp Actions Notice 4), not incremental exposure (A7).
A27: TOTAL — INCLUDED LOANS ONLY | G27: =SUMIF(N5:N26,"Y",G5:G26) -> 478017000 | J27: =SUMIF(N5:N26,"Y",J5:J26) -> 11395308 | K27: =SUMIF(N5:N26,"Y",K5:K26) -> 12398058 | L27: =SUMIF(N5:N26,"Y",L5:L26) -> 1002750
B29: Memo: loans excluded as duplicates (for reference, not in total)
B30: Face value of excluded duplicate/superseded lines: | G30: =SUMIF(N5:N26,"N",G5:G26) -> 145048000

Sheet Debt_Facilities
A1: Fund-Level Debt Facilities — Cost of Leverage
A2: Sources: 02_Greystone_Facility_Agreement_Excerpt.txt, 05_Revolver_Utilization_Report.csv, 12_Cash_Ledger_Q4_2025.csv. See Assumption A13.
A4: 1. GREYSTONE REVOLVER (fund-level, $300mm committed)
A5: Committed amount (USD) | D5: 300000000 | H5: 02_Facility Agmt §2.01
A6: Pricing | D6: Term SOFR + 11.448bps CSA + 275bps margin (post 01-Jul-24; was 3M LIBOR + 275bps pre-transition) | H6: 02_Facility Agmt §2.05
A7: Commitment fee (undrawn) | D7: 0.004 | H7: 02_Facility Agmt §2.09(a), 40bps p.a.
A8: Upfront fee (capitalised into principal, day 1) | D8: 0.0075 | H8: 02_Facility Agmt §2.09(c) — loan balance on Bank's books > cash actually received
A9: Asset coverage covenant | D9: ≥ 1.55x Borrowing Base Assets / (Revolver + Term Loan o/s) | H9: 02_Facility Agmt §6.01
A10: Q3-25 interest paid (actual, cash ledger) | D10: -5250000 | H10: 12_Cash_Ledger 15-Oct-25, DEBT_INT_OUT
A11: Q3-25 commitment fee paid (actual, cash ledger) | D11: -93750 | H11: 12_Cash_Ledger 15-Oct-25, DEBT_FEE_OUT (40bps × avg undrawn $187.5mm × 90/360)
A12: Implied avg. undrawn Q3 (back-solved from fee) | D12: =ABS(D11)/D7/(90/360) -> 93750000 | H12: Back-solved: fee / (rate × day fraction)
A13: Implied avg. drawn Q3 (committed − undrawn) | D13: =D5-D12 -> 206250000 | H13: 300mm committed less implied undrawn
A14: Q4-25 drawn balance / interest | D14: NOT ISOLATED IN THE DATA PACK — see Assumption A13
A16: 2. IRONBRIDGE TERM LOAN (fund-level, $200mm, bullet)
A17: Principal (USD) | D17: 200000000 | H17: 02_Facility Agmt Art. VIII
A18: Coupon | D18: 0.0825 | H18: 02_Facility Agmt Art. VIII, fixed, semi-annual
A19: Maturity | D19: 22-Feb-2029 (bullet) | H19: 02_Facility Agmt Art. VIII
A20: H2-25 interest paid (actual, cash ledger) | D20: -8250000 | H20: 12_Cash_Ledger 31-Dec-25, DEBT_INT_OUT
A21: Check: 8.25% × $200mm × ½ year | D21: =200000000*0.0825/2 -> 8250000 | H21: Formula cross-check vs. cash ledger figure above
A23: 3. LOAN-LEVEL REVOLVERS (embedded in borrower facilities, not fund leverage)
A24: Facility | B24: Obligor | C24: Commitment | D24: Drawn 31-Dec-25 | E24: Undrawn | F24: Util. Fee (bps) | G24: Q4 Interest/Fee Cash (USD) | H24: Notes
A25: WTM-L-0006 / BLA-0156 | B25: Solara Content Partners | C25: 50000000 | D25: 32000000 | E25: 18000000 | F25: 25 | G25: 685143 | H25: Util. fee triggered above 50% utilisation per side letter (05_Revolver report, 09/25 note).
A26: BLA-0128 | B26: Orion Studios Holdings LLC | C26: 15000000 | D26: 9750000 | E26: 5250000 | F26: 0 | G26: 189150 | H26: Drawdown frozen post-15-Oct-25 restructuring (05_Revolver report note).

Sheet IRS
A1: Interest Rate Swap — GTB-IRS-2024-0342 — Hedge Effectiveness
A2: Sources: 07_IRS_Confirmation_Greystone.txt, 10_Broker_MTM_Statement_Dec2025.json, 12_Cash_Ledger_Q4_2025.csv, 11_PM_Trading_Notes.txt. See Assumptions A1, A14.
A4: TERMS
A5: Notional (USD) | B5: 250000000
A6: Fund pays fixed | B6: 0.04425
A7: Fund receives floating | B7: USD-LIBOR-BBA 3M → fallback Term SOFR + 26.161bps CSA (post-cessation)
A8: Trade / Effective / Termination | B8: 28-Feb-24 / 04-Mar-24 / 04-Mar-27
A9: Hedge accounting elected? | B9: No (per deal memo)
A11: BASIS MISMATCH (facility vs. swap, post-LIBOR)
A12: Greystone revolver CSA (fallback) | B12: 0.0011448
A13: IRS floating leg CSA (fallback) | B13: 0.00026161
A14: Persistent annual basis absorbed by the fund | B14: =B13-B12 -> -0.00088319 | F14: Sticky note 03-Jul-24 (N.R.): 26.161 − 11.448 = 14.713bps/yr; desk decided to live with it, not unwind.
A16: HEDGE SIZING
A17: Combined facility commitments | B17: 500000000
A18: PM-estimated effective floating exposure (~50% avg revolver util. blended) | B18: 350000000
A19: IRS notional | B19: 250000000
A20: Under-hedged notional gap | B20: =B18-B19 -> 100000000 | F20: Source: PM Trading Notes — IRS section, explicit (A14). Facility-committed sizing rationale ($500M less assumed 50% revolver utilisation = $250M) is in the original deal memo but produces a smaller notional than PM's own effective-exposure estimate.
A22: HEDGE EFFECTIVENESS (per PM's specified measure)
F23: PM formula: (swap P&L + change in facility interest expense) / notional ≈ 0 if hedging well.
A24: Swap fair value to Fund, 31-Dec-25 (MTM) | B24: -3842000 | F24: 07_IRS confirm / 10_Broker MTM
A25: Swap accrued (unpaid) since last pay date | B25: -287000 | F25: 10_Broker MTM
A26: Q3-25 net swap cash settlement (real entry, per A1) | B26: -1725000 | F26: 12_Cash_Ledger 04-Oct-25, adopted per Assumption A1
A27: Q3-25 duplicate/erroneous entry excluded (memo only) | B27: 1250000 | F27: 12_Cash_Ledger — EXCLUDED, see A1
A28: Facility interest cost, Q3-25 (actual, cash ledger) | B28: -5250000 | F28: 12_Cash_Ledger 15-Oct-25, DEBT_INT_OUT
A29: Prior-quarter facility interest cost for comparison | B29: NOT PROVIDED IN DATA PACK — cannot compute a period-over-period Δ facility cost
A31: CONCLUSION
A32: The swap's negative $3.84M mark, viewed alone, looks like a losing trade — but that is the wrong lens per PM notes: rates fell, so the Fund pays more on the fixed leg than it receives floating, while the Greystone revolver's own floating cost fell by a comparable amount over the same period. Two things limit how precisely "hedge effectiveness" can be proven here: (i) the data pack has no time series of Q4 facility interest expense to compare against the swap's Q4 P&L, and (ii) the swap notional ($250mm) is undersized relative to PM's own $350mm effective-exposure estimate, so even a perfectly offsetting swap would only hedge ~71% of the floating exposure. Directionally the hedge is real and correctly signed (pay-fixed swap against a pay-floating facility), but full quantitative proof of effectiveness is a data gap, not a model conclusion — flagged rather than estimated.

Sheet CDS
A1: Credit Default Swaps — Direction, Settlement & Recognition
A2: Sources: 06_CDS_Confirmation_OrionStudios.txt, 10_Broker_MTM_Statement_Dec2025.json, 11_PM_Trading_Notes.txt, 16_Corporate_Actions_Notices.txt, 12_Cash_Ledger. See Assumption A2.
A4: Trade Ref | B4: Reference Entity | C4: Notional (USD) | D4: Fund Direction | E4: Coupon (bps) | F4: Fair Value 31-Dec-25 (USD) | G4: Q4 Premium Cash (USD) | H4: Purpose | I4: Notes
A5: ARI-WTM-CDS-0011 | B5: Orion Studios Holdings LLC | C5: 25000000 | D5: Protection BUYER (Fixed Rate Payer) | E5: 100 | F5: 0 | G5: -62500 | H5: Hedge (long loan exposure) | I5: Credit event 10-Sep-25; auction 24-Sep-25 at 42.25; settlement USD 14,437,500 treated as a RECEIPT to the Fund per Assumption A2 (confirm's plain reading + PM's paying-not-receiving premium evidence + cash ledger booking). Position now closed.
A6: ARI-WTM-CDS-0018 | B6: Lumivue Streaming Corp | C6: 40000000 | D6: Protection BUYER (Fixed Rate Payer) | E6: 250 | F6: 1245000 | G6: -250000 | H6: Hedge (long unitranche) | I6: Live; long protection in the money as credit spreads have widened — correctly offsetting the underlying loan (both PM notes and broker statement agree on sign here).
A7: ARI-WTM-CDS-0022 | B7: Timberline Entertainment Group Inc | C7: 30000000 | D7: Protection SELLER (Floating Rate Payer) | E7: 380 | F7: -720000 | G7: 285000 | H7: Income generation (unrelated name) | I7: Pure carry trade — NOT linked to Timberline Music Rights I LLC loan (different, unrelated obligor; Compliance confirmed no netting). Spread widened 340→~420bps since inception; position under water at YE but PM is holding.
A9: ORION SETTLEMENT MECHANICS (CDS-0011)
A10: Notional (USD) | B10: 25000000
A11: Auction final price (% of par) | B11: 0.4225
A12: Recovery amount (Notional × price) | B12: =B10*B11 -> 10562500
A13: Settlement amount = Notional × (100% − price) | B13: =B10*(1-B11) -> 14437500
A14: Direction (per Assumption A2) | B14: Fund receives settlement
A16: OFFSET vs. MEZZ WRITEDOWN
A17: Orion mezz face value (WTM-L-0002) | B17: 25000000
A18: Mezz recovery mark (= CDS auction price, per Assumption A5) | B18: 0.4225
A19: Mezz writedown from par | B19: =B17*(1-B18) -> 14437500
A20: CDS settlement receipt (from above) | B20: =B13 -> 14437500
A21: Net P&L impact of the Orion event (CDS gain less mezz writedown) | B21: =B20-B19 -> 0
A22: Reads ~$0 by construction: mezz was marked to the SAME auction price used to size the CDS settlement (Assumption A5), which is the point of the hedge — the residual is the senior loan (still money-good) plus the RSA warrants (near-zero) and the 100bps premium paid over the trade's life.

Sheet FX_Forwards
A1: FX Forwards — Hedge Direction & Settlement P&L
A2: Sources: 08_FX_Forward_Confirmations.txt, 10_Broker_MTM_Statement_Dec2025.json, 16_Corporate_Actions_Notices.txt. See Assumptions A3, A6.
A4: Client Ref | B4: Pair | C4: Fund Position (as executed) | D4: Notional | E4: Contract Rate | F4: Fixing/Current Rate | G4: Settlement / MTM P&L (USD) | H4: Hedges | I4: Notes / Direction Analysis
A5: WTM-FX-0044 | B5: GBP/USD | C5: Fund BUYS GBP 22.4mm / SELLS USD 30.464mm | D5: 22400000 | E5: 1.36 | F5: 1.2585 | G5: -2273600 | H5: Thornbury GBP loan (BLA-0088) | I5: PM notes flag this as the WRONG direction: to hedge a GBP RECEIPT (loan coupon/principal), the Fund should be SELLING GBP forward, not buying it. As executed, the forward moves the SAME direction as the underlying loan — it doubles exposure rather than offsetting it (Assumption A3: model as-executed, per PM instruction).
A6: WTM-FX-0045 | B6: USD/JPY | C6: Fund SELLS JPY 2,400mm / BUYS USD 15,789,474 | D6: 2400000000 | E6: 152 | F6: 156.85 | G6: -493860 | H6: Haruki Anime Studios KK loan (BLA-0102/WTM-L-0009) | I6: Correct hedge DIRECTION (selling JPY forward against a JPY receivable is right), but under-SIZED: loan notional reset Nov-25 to JPY 2,737,800,000 while forward stayed at the original JPY 2,400,000,000 — shortfall of JPY 337,800,000 (≈ USD 2.15mm at YE spot), Assumption A6. Settlement sign per source email's own correction (fund sold JPY too cheap = loss).
A7: WTM-FX-0046 | B7: EUR/USD | C7: Client BUYS EUR 4.75mm / SELLS USD 5.15mm | D7: 4750000 | E7: 1.085 | F7: 1.0655 | G7: -92625 | H7: UNCONFIRMED — booked outside the loan-hedging program | I7: Purpose not stated in the confirm email; not tied to any loan cashflow in the data pack. Modelled here as a stand-alone / speculative position, not a hedge, pending strategy-tag confirmation (per the FX desk's own note).
A9: HEDGE EFFECTIVENESS SUMMARY
A10: Hedge | B10: Underlying Direction | C10: Forward Direction (as-executed) | D10: Offsetting? | E10: Comment
A11: GBP (Thornbury) | B11: Fund RECEIVES GBP (loan coupon/principal) → exposed to GBP weakening | C11: Fund BUYS GBP forward (same direction as receipt) | D11: NO — compounds exposure | E11: As booked, a GBP depreciation loses on BOTH the loan translation and the forward. Should be selling GBP forward.
A12: JPY (Haruki) | B12: Fund RECEIVES JPY → exposed to JPY weakening | C12: Fund SELLS JPY forward (correct direction) | D12: PARTIALLY — under-sized | E12: Direction is right; size is stale post notional-reset. Effectiveness degrades as the loan notional grows relative to the static hedge.
A13: EUR (Equinox / unconfirmed) | B13: No stated underlying link | C13: Fund (client) BUYS EUR forward | D13: N/A — not a confirmed hedge | E13: Should be treated as a directional/speculative FX position for KPI purposes until strategy tag is confirmed.

Sheet Options
A1: Options — Open Positions & Q4 Realized Activity
A2: Sources: 09_Options_Positions_PrimeBroker.tsv, 12_Cash_Ledger_Q4_2025.csv, 11_PM_Trading_Notes.txt. See Assumptions A9-A11.
A4: OPEN POSITIONS, 31-DEC-2025
A5: Ticker | B5: Underlying | C5: Type | D5: Right | E5: Contracts | F5: Strike | G5: Fair Value (USD) | H5: Notes
A6: ORNX | B6: Orion Studios Holdings Corp | C6: LISTED | D6: CALL | E6: -500 | F6: 12 | G6: -2500 | H6: Short call — loan-linked equity, strategy tag pending PM confirmation.
A7: ORNX | B7: Orion Studios Holdings Corp | C7: LISTED | D7: PUT | E7: 500 | F7: 7.5 | G7: 42500 | H7: Long protective put.
A8: LMVU | B8: Lumivue Streaming Corp | C8: LISTED | D8: CALL | E8: 200 | F8: 85 | G8: 157000 | H8: Long call.
A9: LMVU | B9: Lumivue Streaming Corp | C9: LISTED | D9: PUT | E9: -200 | F9: 75 | G9: -24000 | H9: Short put, premium collected.
A10: EMBL | B10: Emberlight Records Group ADR | C10: LISTED | D10: CALL | E10: -800 | F10: 22.5 | G10: -132000 | H10: Short call vs. equity co-invest.
A11: FRGF | B11: Frostgate Films Ltd (GDR) | C11: OTC | D11: PUT | E11: 1 | F11: 4.2 | G11: 65442 | H11: GBp-denominated; USD equivalent used per Assumption A9 (raw report figure of GBp 52,000 was a mislabeled system error).
A12: PRMK | B12: Prismrock Live Events Inc | C12: LISTED | D12: CALL | E12: 300 | F12: 18 | G12: 19500 | H12: Long call, directional.
A13: SLRA | B13: Solara Content Partners | C13: OTC | D13: CALL | E13: 1 | F13: 100 | G13: 0 | H13: Level-3 / model-marked (62% vol, unverified) — EXCLUDED from recognized P&L per Assumption A10; memo fair value per broker statement was $117,500.
A14: TOTAL RECOGNIZED FAIR VALUE (excl. SLRA, Assumption A10) | G14: =SUM(G6:G13) -> 125942
A16: Q4 REALIZED ACTIVITY (closes / expiries / exercises)
A17: Date | B17: Position | C17: Event | D17: Realized P&L (USD) | H17: Notes
A18: 2025-10-22 | B18: LMVU PUT 70, Nov-25 exp, 100 lots long | C18: Closed @ 0.10 (opened @ 1.85) | D18: -17500 | E18: Realized loss.
A19: 2025-11-15 | B19: ORNX CALL 15, Nov-25 exp, 300 lots short | C19: Expired worthless (opened @ 2.20) | D19: 66000 | E19: Realized gain, premium kept.
A20: 2025-12-20 | B20: EMBL PUT 20, Dec-25 exp, 400 lots long | C20: Expired worthless (opened @ 0.95) | D20: -38000 | E20: Realized loss.
A21: 2025-12-30 | B21: LMVU CALL 90, Dec-25 exp, 150 lots long | C21: Exercised — physical settlement | D21: 0 | E21: No option P&L — rolls into equity co-invest cost basis at $95.20/sh (strike $90.00 + premium $5.20). Excluded from options P&L per Assumption A11; cash outflow $1,350,000 tie-out on Cash_Recon tab.
A22: TOTAL Q4 REALIZED OPTIONS P&L | D22: =SUM(D18:D21) -> 10500

Sheet Leases
A1: Leased Assets Registry — Treatment & Sleeve Cost
A2: Sources: 14_Leased_Assets_Registry.csv, 11_PM_Trading_Notes.txt, 16_Corporate_Actions_Notices.txt. See Assumption A4.
A4: Lease ID | B4: Category | C4: Lessor | D4: Ccy | E4: Payment (native) | F4: Payment (USD) | G4: Annualized (USD) | H4: Notes
A5: LEASE-NYC-M | B5: Office — NYC | C5: Bradford Realty Trust | D5: USD | E5: 142000 | F5: 142000 | G5: =F5*12 -> 1704000 | H5: Ordinary fund opex, no dispute.
A6: LEASE-LA-M | B6: Office — LA | C6: Westside Property LLC | D6: USD | E6: 88000 | F6: 88000 | G6: =F6*12 -> 1056000 | H6: Ordinary fund opex, no dispute.
A7: LEASE-CMP-M | B7: IT — Managed cloud | C7: Northwind Systems Corp | D7: USD | E7: 215000 | F7: 215000 | G7: =F7*12 -> 2580000 | H7: Ordinary fund opex, no dispute.
A8: LEASE-CML-Q | B8: Content Library — Longwood catalog | C8: Longwood Music Trust | D8: USD | E8: 450000 | F8: 450000 | G8: =F8*4 -> 1800000 | H8: DISPUTED treatment (FA: opex vs. entertainment-sleeve revenue; PM: investment cost of THIS sleeve). Adopted here per Assumption A4 — treated as an investment cost of the credit/derivatives sleeve, netted against the sub-licence royalty income it generates (see KPI_Summary).
A9: LEASE-CML-Q2 | B9: Content Library — Greystone Bridge Film Library | C9: Greystone Media Holdings | D9: USD | E9: 85000 | F9: 85000 | G9: =F9*4 -> 340000 | H9: Smaller catalog; opex treatment AGREED (not disputed) — unrelated to Greystone Trust Bank despite the name.
A10: LEASE-JPY-Q | B10: Content Library (JPY) — Nishimura Anime Titles | C10: Nishimura Rights KK | D10: JPY | E10: 32500000 | F10: 207205 | G10: =F10*4 -> 828820 | H10: Payment in JPY, UNHEDGED — not mentioned in the Fund Overview memo or PM notes; folded into FX exposure for completeness. USD converted at YE spot 156.85 (inception assumption was $217,000/qtr).
A11: TOTAL ANNUALIZED LEASE COST | G11: =SUM(G5:G10) -> 8308820
A12: Of which treated as a sleeve investment cost (Longwood + Nishimura, Assumption A4) | G12: =G8+G10 -> 2628820
A14: LONGWOOD TRUE-UP, CY2025 (16_Corp Actions Notice 6)
A15: Gross sub-licence revenue, CY2025 | B15: 6275000
A16: Base fixed quarterly payments, annualized | B16: 1800000
A17: Excess over base | B17: =B15-B16 -> 4475000
A18: True-up rate | B18: 0.12
A19: True-up payable (accrue 31-Dec-25; cash 31-Mar-26) | B19: =B17*B18 -> 537000

Sheet Cash_Recon
A1: Q4-2025 Cash Ledger — Categorized & Flagged Items
A2: Source: 12_Cash_Ledger_Q4_2025.csv (raw order preserved). Flags reproduce the ledger's own “CHECK” notes plus items resolved via Assumptions A1-A2.
A4: Value Date | B4: Description | C4: Category | D4: Amount (USD) | E4: Flag | F4: Resolution / Note
A5: 2025-10-01 | B5: Interest received - Lumivue unitranche Q3 coupon | C5: LOAN_INT_IN | D5: 2172000 | F5: Ties to Loan_Book WTM-L-0005.
A6: 2025-10-01 | B6: Interest received - Prismrock Live Events Q3 coupon | C6: LOAN_INT_IN | D6: 475000 | F6: Ties to Loan_Book WTM-L-0004.
A7: 2025-10-02 | B7: Interest received - Solara Content Q3 coupon (drawn portion) | C7: LOAN_INT_IN | D7: 472500 | F7: Ties to Loan_Book WTM-L-0006 / Debt_Facilities.
A8: 2025-10-02 | B8: Unused facility fee Solara Q3 | C8: LOAN_FEE_IN | D8: 29143 | F8: Ties to Debt_Facilities loan-level revolvers.
A9: 2025-10-03 | B9: Timberline Music Rights coupon Q3 (partial - transfer) | C9: LOAN_INT_IN | D9: 262500 | F9: Pre-transfer accrual, Beta-reported; consistent with Loan_Book A7 dedup.
A10: 2025-10-03 | B10: Emberlight Records monthly coupon Sep25 | C10: LOAN_INT_IN | D10: 464625 | F10: Ties to Loan_Book WTM-L-0003.
A11: 2025-10-04 | B11: IRS payment received (net) Q3 | C11: SWAP_NET | D11: 1250000 | E11: EXCLUDED (A1) | F11: Ledger's own note: one of these two same-day entries is an error. Excluded from KPI cash flow per Assumption A1.
A12: 2025-10-04 | B12: IRS payment made (net) Q3 | C12: SWAP_NET | D12: -1725000 | E12: ADOPTED (A1) | F12: Retained as the true Q3 net settlement — consistent with swap's negative YE mark. See IRS tab.
A13: 2025-10-15 | B13: Greystone revolver interest payment | C13: DEBT_INT_OUT | D13: -5250000 | F13: Ties to Debt_Facilities Greystone section.
A14: 2025-10-15 | B14: Greystone revolver commitment fee Q3 | C14: DEBT_FEE_OUT | D14: -93750 | F14: Ties to Debt_Facilities; used to back-solve implied undrawn balance.
A15: 2025-10-31 | B15: Content library lease payment - Longwood Music Trust | C15: LEASE_OUT | D15: -450000 | F15: Ties to Leases tab, LEASE-CML-Q; treatment per Assumption A4.
A16: 2025-11-04 | B16: Office lease payment - NYC | C16: LEASE_OUT | D16: -142000 | F16: Ordinary opex, ties to Leases.
A17: 2025-11-04 | B17: Office lease payment - LA | C17: LEASE_OUT | D17: -88000 | F17: Ordinary opex, ties to Leases.
A18: 2025-11-04 | B18: Northwind Systems managed cloud lease Nov | C18: LEASE_OUT | D18: -215000 | F18: Ordinary opex, ties to Leases.
A19: 2025-11-10 | B19: CDS premium payment - Orion protection Q3 | C19: SWAP_PREM_OUT | D19: -62500 | F19: Confirms Fund PAYS the Orion premium — supports protection-BUYER direction, Assumption A2.
A20: 2025-11-10 | B20: CDS premium payment - Lumivue protection Q3 | C20: SWAP_PREM_OUT | D20: -250000 | F20: Ties to CDS-0018, protection buyer.
A21: 2025-11-10 | B21: CDS premium received - Timberline Ent short protection Q3 | C21: SWAP_PREM_IN | D21: 285000 | F21: Ties to CDS-0022, protection seller (income trade).
A22: 2025-11-20 | B22: Sub-license royalty received - streaming catalog | C22: ROYALTY_IN | D22: 875000 | F22: Pulled into sleeve yield per Assumption A4 (paired against Longwood lease cost).
A23: 2025-11-20 | B23: Sub-license royalty received - sync fees | C23: ROYALTY_IN | D23: 320000 | F23: Pulled into sleeve yield per Assumption A4.
A24: 2025-11-25 | B24: FX Forward roll - GBP/USD (net cash on roll) | C24: FX_ROLL | D24: -96000 | E24: UNRESOLVED | F24: Ledger flags “CHECK sign.” Distinct from the $2,273,600 fixing-date settlement loss on FX_Forwards tab — likely a roll/points cost, not independently provable from the data given. Shown as-is, not re-signed.
A25: 2025-12-01 | B25: Bridge loan interest Greystone Bridge | C25: LOAN_INT_IN | D25: 127000 | F25: Ties to Loan_Book WTM-L-0012.
A26: 2025-12-15 | B26: Capital call #7 receipt from LPs | C26: LP_CAPITAL_IN | D26: 25000000 | F26: Ties to LP_Capital tab, CC-2025-07.
A27: 2025-12-15 | B27: LP distribution paid | C27: LP_DIST_OUT | D27: -15000000 | F27: Ties to LP_Capital tab, DIST-2025-04.
A28: 2025-12-20 | B28: Options premium received - EMBL calls sold | C28: OPT_PREM_IN | D28: 88000 | F28: Consistent w/ Options tab EMBL short call entry premium (800 × $1.10).
A29: 2025-12-30 | B29: Option exercise - LMVU call exercised (cash for shares) | C29: OPT_EX_OUT | D29: -1350000 | F29: Ties to Options tab activity log — rolls into equity co-invest, excluded from options P&L (A11).
A30: 2025-12-31 | B30: Ironbridge term loan interest H2 | C30: DEBT_INT_OUT | D30: -8250000 | F30: Ties to Debt_Facilities Ironbridge section.
A31: 2025-12-31 | B31: Orion mezz Q4 coupon (NOT RECEIVED - accrued) | C31: LOAN_INT_ACCR | D31: 0 | F31: Ties to Loan_Book WTM-L-0002 — $640,625 accrued, not cash; recognition-vs-cash gap.
A32: 2025-09-28 | B32: Cash settlement CDS Orion credit event | C32: SWAP_SETTLE | D32: 14437500 | E32: BOOKED WITH LAG (A2) | F32: Value date 28-Sep-25 but booked 08-Jan-26 — direction assumed RECEIPT per Assumption A2; see CDS tab.
A33: 2025-12-30 | B33: Bank interest income on operating cash | C33: MISC_IN | D33: 45000
A34: 2025-10-05 | B34: Management fee to GP - Q3 | C34: GP_FEE_OUT | D34: -950000 | F34: 1.5% p.a. on committed capital / 4, per LPA.
A35: 2025-12-05 | B35: Management fee to GP - Q4 | C35: GP_FEE_OUT | D35: -950000 | F35: 1.5% p.a. on committed capital / 4, per LPA.
A36: 2025-11-15 | B36: Fund audit fee - Whitfield Hale 2025 | C36: ADMIN_OUT | D36: -185000
A37: 2025-12-31 | B37: Fund administrator fee Q4 | C37: ADMIN_OUT | D37: -75000
A38: 2025-11-30 | B38: LP capital call refund - Cayman feeder over-called Q3 | C38: LP_CAPITAL_OUT | D38: -3200000 | F38: Ties to LP_Capital tab, CC-2025-06R.
A39: NET CASH MOVEMENT, Q4-25 (excluding excluded/duplicate entry) | D39: =SUM(D5:D38)-1250000 -> 6721018

Sheet Concentration_Test
A1: Greystone Covenant — Single-Name Concentration Test (Orion Studios Holdings LLC)
A2: Sources: 02_Greystone_Facility_Agreement_Excerpt.txt §6.02, 16_Corporate_Actions_Notices.txt Notice 5, 15_Counterparty_Exposure_Snapshot.csv. See Assumption A5.
A4: COVENANT (02_Facility Agmt §6.02(i))
A5: Fund Total NAV (estimated, pending audit) | B5: 385000000
A6: Single-name concentration limit | B6: 0.125
A7: Limit in USD | B7: =B5*B6 -> 48125000
A9: ORION EXPOSURE COMPONENTS
A10: Component | B10: At Par / Full Notional | C10: At Recovery-Adjusted (A5) | D10: Source
A11: Senior loan (WTM-L-0001) | B11: 45000000 | C11: 45000000 | D11: Loan_Book — money-good, no adjustment.
A12: Mezz loan (WTM-L-0002) | B12: 25000000 | C12: 10562500 | D12: Loan_Book / CDS tab — recovery mark = 42.25% × face per Assumption A5.
A13: Revolver draw (BLA-0128) | B13: 9750000 | C13: 9750000 | D13: Loan_Book.
A14: Long CDS protection (netted — same obligor) | B14: -25000000 | C14: -25000000 | D14: CDS tab — netting permitted under §6.02 since Reference Entity = loan obligor, same legal entity.
A15: Long put options (equity, small) | B15: 375000 | C15: 375000 | D15: Options tab context (500 ORNX puts × 100 × $7.50 notional).
A16: Short call options (equity, small) | B16: 600000 | C16: 600000 | D16: Options tab context (500 ORNX calls × 100 × $12.00 notional).
A18: RESULT
A19: Total exposure — mezz AT PAR, CDS netted | B19: =SUM(B11:B16) -> 55725000 | C19: =B19<=$B$7 -> FALSE | D19: =IF(B19<=$B$7,"UNDER LIMIT","OVER LIMIT") -> OVER LIMIT
A20: Total exposure — mezz AT RECOVERY (A5), CDS netted | B20: =SUM(C11:C16) -> 41287500 | C20: =B20<=$B$7 -> TRUE | D20: =IF(B20<=$B$7,"UNDER LIMIT","OVER LIMIT") -> UNDER LIMIT
A21: Total exposure — mezz AT PAR, CDS NOT netted (position treated as closed) | B21: =SUM(B11:B16)-B14 -> 80725000 | C21: =B21<=$B$7 -> FALSE | D21: =IF(B21<=$B$7,"UNDER LIMIT","OVER LIMIT") -> OVER LIMIT
A23: The compliance outcome hinges entirely on how the restructured mezz is carried and whether the CDS position (now closed post-settlement) still qualifies for netting. Recovery-adjusted mezz + CDS netting (row 2, our recommended treatment per Assumption A5) brings the Fund UNDER the 12.5% limit. At-par mezz without CDS netting (row 3, since the CDS position technically closed on settlement and Article 6.02 netting language contemplates a live protection position) pushes the Fund OVER. Greystone's own covenant notice (16_Corp Actions Notice 5) shows the same range of outcomes and records a 30-day standstill pending resolution — this is a genuine open item, not a modeling error, and is presented here as a scenario range rather than a single answer. NOTE: our recovery-adjusted total ($41,287,500) does not exactly match the figure in Greystone's own covenant notice for the equivalent scenario ($44,306,000) — the components listed in that notice do not foot to its own stated total either; treat both as approximate pending the agent's formal resolution.

Sheet LP_Capital
A1: LP Capital Calls & Distributions — Summary
A2: Source: 13_LP_Capital_Calls_and_Distributions.txt
A4: CAPITAL CALLS
A5: Notice | B5: Date | C5: Amount (USD) | D5: Purpose / Note
A6: CC-2024-01 | B6: 2024-02-20 | C6: 60000000 | D6: Initial deployment and working capital.
A7: CC-2024-02 | B7: 2024-05-15 | C7: 90000000 | D7: Orion Studios term loan, Emberlight Records origination.
A8: CC-2024-03 | B8: 2024-09-20 | C8: 75000000 | D8: Lumivue unitranche funding.
A9: CC-2025-01 | B9: 2025-01-15 | C9: 50000000 | D9: General deployment.
A10: CC-2025-02 | B10: 2025-04-25 | C10: 40000000 | D10: Frostgate (GBP), Ridgeline Post-Production. GBP-electing LPs booked at call-date spot (1.2870) vs. committed reference rate (1.24), producing an unresolved ~$203,980 fx-adjustment delta (flagged in memo, not yet reclassified).
A11: CC-2025-03 | B11: 2025-06-10 | C11: 25000000 | D11: Haruki Anime co-production loan; JPY option offered but not elected.
A12: CC-2025-06 | B12: 2025-08-05 | C12: 60000000 | D12: Timberline Music Rights, various derivative margin. OVER-CALLED by $3,200,000, refunded 30-Nov-25 (CC-2025-06R).
A13: CC-2025-07 | B13: 2025-12-05 | C13: 25000000 | D13: Working capital, opportunistic.
A14: CC-2025-06R (refund) | B14: 2025-11-30 | C14: -3200000 | D14: Over-call adjustment refund.
A15: NET CAPITAL CALLED | C15: =SUM(C6:C14) -> 421800000
A17: DISTRIBUTIONS
A18: Notice | B18: Date | C18: Amount (USD) | D18: Character
A19: DIST-2024-01 | B19: 2024-09-30 | C19: 5000000 | D19: Income — 100% to LPs, preferred return not yet reached.
A20: DIST-2025-01 | B20: 2025-03-31 | C20: 8500000 | D20: Income (loan coupons).
A21: DIST-2025-02 | B21: 2025-06-30 | C21: 10200000 | D21: Income.
A22: DIST-2025-03 | B22: 2025-09-30 | C22: 11750000 | D22: Income (~$9.0mm) + return of capital (~$2.75mm).
A23: DIST-2025-04 | B23: 2025-12-15 | C23: 15000000 | D23: Income (~$9.0mm) + ROC (~$3.5mm) + CDS settlement gain (~$2.5mm) — ties to Orion settlement on CDS tab.
A24: TOTAL DISTRIBUTED | C24: =SUM(C19:C23) -> 50450000
A26: Preferred return (7% simple on paid-in) fully paid? | C26: No — per IR compilation; no carry paid to date.
